<?xml version='1.0'?>

<robot name="udacity_bot" xmlns:xacro="http://www.ros.org/wiki/xacro">

<xacro:include filename="$(find udacity_bot)/urdf/udacity_bot.gazebo" />

  <link name="robot_footprint"></link>

  <link name='chassis'>
    <pose>0 0 0.1 0 0 0</pose>
    <inertial>
      <mass value="15.0"/>
      <origin xyz="0.0 0 0" rpy=" 0 0 0"/>
      <inertia
          ixx="0.2125" ixy="0" ixz="0"
          iyy="0.0625" iyz="0"
          izz="0.25"
      />
    </inertial>

    <collision name='chassis_collision'>
      <origin xyz="0 0 0" rpy=" 0 0 0"/> 
      <geometry>
        <box size=".4 .2 .1"/>
      </geometry>
    </collision>

    <visual name='chassis_visual'>
      <origin xyz="0 0 0" rpy=" 0 0 0"/>
      <geometry>
        <box size=".4 .2 .1"/>
      </geometry>
      <material name="black_metal">
	<color rgba="0.1 0.1 0.1 1"/>
      </material>
    </visual>

    <collision name='front_caster_collision'>
      <origin xyz="0.15 0 -0.05" rpy=" 0 0 0"/>
      <geometry>
        <sphere radius="0.05"/>
      </geometry>
      <surface>
        <friction>
          <ode>
            <mu>0</mu>
            <mu2>0</mu2>
            <slip1>1.0</slip1>
            <slip2>1.0</slip2>
          </ode>
        </friction>
      </surface>
    </collision>

    <visual name='front_caster_visual'>
      <origin xyz="0.15 0 -0.05" rpy=" 0 0 0"/>
      <geometry>
        <sphere radius="0.05"/>
      </geometry>
      <material name="black_metal">
	<color rgba="0.1 0.1 0.1 1"/>
      </material>
    </visual>

    <collision name='back_caster_collision'>
      <origin xyz="-0.15 0 -0.05" rpy=" 0 0 0"/>
      <geometry>
        <sphere radius="0.05"/>
      </geometry>
      <surface>
        <friction>
          <ode>
            <mu>0</mu>
            <mu2>0</mu2>
            <slip1>1.0</slip1>
            <slip2>1.0</slip2>
          </ode>
        </friction>
      </surface>
    </collision>

    <visual name='back_caster_visual'>
      <origin xyz="-0.15 0 -0.05" rpy=" 0 0 0"/>
      <geometry>
        <sphere radius="0.05"/>
      </geometry>
      <material name="black_metal">
	<color rgba="0.1 0.1 0.1 1"/>
      </material>
    </visual>
  </link>

  <link name='left_wheel'>

    <inertial>
      <mass value="5.0"/>
      <origin xyz="0.0 0 0" rpy=" 0 0 0"/>
      <inertia
          ixx="0.046" ixy="0" ixz="0"
          iyy="0.046" iyz="0"
          izz="0.025"
      />
    </inertial>

    <collision name='left_wheel_collision'>
      <origin xyz="0 0 0" rpy=" 0 1.5707 1.5707"/> 
      <geometry>
        <cylinder radius=".1" length=".05"/>
      </geometry>
    </collision>

    <visual name='left_wheel_visual'>
      <origin xyz="0 0 0" rpy=" 0 1.5707 1.5707"/>
      <geometry>
        <cylinder radius=".1" length=".05"/>
      </geometry>
    </visual>
      <material name="gold">
        <color rgba="1 0.549 0 1"/>
      </material>
  </link>

  <link name='right_wheel'>

    <inertial>
      <mass value="5.0"/>
      <origin xyz="0.0 0 0" rpy=" 0 0 0"/>
      <inertia
          ixx="0.046" ixy="0" ixz="0"
          iyy="0.046" iyz="0"
          izz="0.025"
      />
    </inertial>

    <collision name='right_wheel_collision'>
      <origin xyz="0 0 0" rpy=" 0 1.5707 1.5707"/> 
      <geometry>
        <cylinder radius=".1" length=".05"/>
      </geometry>
    </collision>

    <visual name='right_wheel_visual'>
      <origin xyz="0 0 0" rpy=" 0 1.5707 1.5707"/>
      <geometry>
        <cylinder radius=".1" length=".05"/>
      </geometry>
      <material name="gold">
        <color rgba="1 0.549 0 1"/>
      </material>
    </visual>
  </link>

  <link name="camera">
    <inertial>
      <mass value="0.1"/>
      <origin xyz="0.0 0 0" rpy=" 0 0 0"/>
      <inertia
          ixx="1e-6" ixy="0" ixz="0"
          iyy="1e-6" iyz="0"
          izz="1e-6"
      />
    </inertial>

    <collision name='camera_collision'>
      <origin xyz="0 0 0" rpy=" 0 0 0"/> 
      <geometry>
        <box size=".05 .05 .05"/>
      </geometry>
    </collision>

    <visual name='camera_visual'>
      <origin xyz="0 0 0" rpy=" 0 0 0"/>
      <geometry>
        <box size=".05 .05 .05"/>
      </geometry>
    </visual>
      <material name="black_metal">
	<color rgba="0.1 0.1 0.1 1"/>
      </material>
  </link> 

  <link name="hokuyo">
    <inertial>
      <mass value="0.1"/>
      <origin xyz="0.0 0 0" rpy=" 0 0 0"/>
      <inertia
          ixx="1e-6" ixy="0" ixz="0"
          iyy="1e-6" iyz="0"
          izz="1e-6"
      />
    </inertial>

    <collision name='hokuyo_collision'>
      <origin xyz="0 0 0" rpy=" 0 0 0"/> 
      <geometry>
        <box size=".1 .1 .1"/>
      </geometry>
    </collision>

    <visual name='hokuyo_visual'>
      <origin xyz="0 0 0" rpy=" 0 0 0"/>
      <geometry>
        <mesh filename="package://udacity_bot/meshes/hokuyo.dae"/>
      </geometry>
    </visual>
      <material name="black_metal">
	<color rgba="0.1 0.1 0.1 1"/>
      </material>
  </link> 



  <joint name="robot_footprint_joint" type="fixed">
    <origin xyz="0 0 0" rpy="0 0 0" />
    <parent link="robot_footprint"/>
    <child link="chassis" />
  </joint>

   <joint type="continuous" name="left_wheel_hinge">
       <origin xyz="0 0.15 0" rpy="0 0 0"/>
       <parent link="chassis"/>
       <child link="left_wheel"/>
       <axis xyz="0 1 0" rpy="0 0 0"/>
       <limit effort="10000" velocity="1000"/>
       <joint_properties damping="1.0" friction="1.0"/>
   </joint>

   <joint type="continuous" name="right_wheel_hinge">
       <origin xyz="0 -0.15 0" rpy="0 0 0"/>
       <parent link="chassis"/>
       <child link="right_wheel"/>
       <axis xyz="0 1 0" rpy="0 0 0"/>
       <limit effort="10000" velocity="1000"/>
       <joint_properties damping="1.0" friction="1.0"/>
   </joint>

<joint type="fixed" name="camera_joint">
      <origin xyz="0.2 0 0" rpy=" 0 0 0"/>
      <parent link="chassis"/>
      <child link="camera"/>
</joint>

<joint type="fixed" name="hokuyo_joint">
      <origin xyz="0.15 0 0.08" rpy=" 0 0 0"/>
      <parent link="chassis"/>
      <child link="hokuyo"/>
</joint>
</robot>
